2025-05-18 18:50:20,942 INFO    Thread-8 (_run_job):45247 [wandb_setup.py:_flush():67] Current SDK version is 0.19.7.dev1
2025-05-18 18:50:20,942 INFO    Thread-8 (_run_job):45247 [wandb_setup.py:_flush():67] Configure stats pid to 45247
2025-05-18 18:50:20,942 INFO    Thread-8 (_run_job):45247 [wandb_setup.py:_flush():67] Loading settings from /home/akshay/.config/wandb/settings
2025-05-18 18:50:20,942 INFO    Thread-8 (_run_job):45247 [wandb_setup.py:_flush():67] Loading settings from /home/akshay/Desktop/DL/da6401_assignment03/wandb/settings
2025-05-18 18:50:20,942 INFO    Thread-8 (_run_job):45247 [wandb_setup.py:_flush():67] Loading settings from environment variables
2025-05-18 18:50:20,942 INFO    Thread-8 (_run_job):45247 [wandb_init.py:setup_run_log_directory():647] Logging user logs to /home/akshay/Desktop/DL/da6401_assignment03/wandb/run-20250518_185020-ma8oyxx4/logs/debug.log
2025-05-18 18:50:20,942 INFO    Thread-8 (_run_job):45247 [wandb_init.py:setup_run_log_directory():648] Logging internal logs to /home/akshay/Desktop/DL/da6401_assignment03/wandb/run-20250518_185020-ma8oyxx4/logs/debug-internal.log
2025-05-18 18:50:20,942 INFO    Thread-8 (_run_job):45247 [wandb_init.py:init():761] calling init triggers
2025-05-18 18:50:20,942 INFO    Thread-8 (_run_job):45247 [wandb_init.py:init():766] wandb.init called with sweep_config: {'batch_size': 64, 'beam_size': 5, 'cell_type': 'RNN', 'decoder_layers': 2, 'dropout': 0.2, 'embed_dim': 256, 'encoder_layers': 2, 'epochs': 10, 'hidden_dim': 64, 'lr': 0.001, 'max_len': 32}
config: {'_wandb': {}}
2025-05-18 18:50:20,942 INFO    Thread-8 (_run_job):45247 [wandb_init.py:init():784] starting backend
2025-05-18 18:50:20,942 INFO    Thread-8 (_run_job):45247 [wandb_init.py:init():788] sending inform_init request
2025-05-18 18:50:20,943 INFO    Thread-8 (_run_job):45247 [backend.py:_multiprocessing_setup():97] multiprocessing start_methods=fork,spawn,forkserver, using: spawn
2025-05-18 18:50:20,943 INFO    Thread-8 (_run_job):45247 [wandb_init.py:init():803] backend started and connected
2025-05-18 18:50:20,943 INFO    Thread-8 (_run_job):45247 [wandb_run.py:_config_callback():1261] config_cb None None {'batch_size': 64, 'beam_size': 5, 'cell_type': 'RNN', 'decoder_layers': 2, 'dropout': 0.2, 'embed_dim': 256, 'encoder_layers': 2, 'epochs': 10, 'hidden_dim': 64, 'lr': 0.001, 'max_len': 32}
2025-05-18 18:50:20,944 INFO    Thread-8 (_run_job):45247 [wandb_init.py:init():896] updated telemetry
2025-05-18 18:50:20,945 INFO    Thread-8 (_run_job):45247 [wandb_init.py:init():920] communicating run to backend with 90.0 second timeout
2025-05-18 18:50:21,536 INFO    Thread-8 (_run_job):45247 [wandb_init.py:init():995] starting run threads in backend
2025-05-18 18:50:21,700 INFO    Thread-8 (_run_job):45247 [wandb_run.py:_console_start():2377] atexit reg
2025-05-18 18:50:21,701 INFO    Thread-8 (_run_job):45247 [wandb_run.py:_redirect():2227] redirect: wrap_raw
2025-05-18 18:50:21,701 INFO    Thread-8 (_run_job):45247 [wandb_run.py:_redirect():2292] Wrapping output streams.
2025-05-18 18:50:21,701 INFO    Thread-8 (_run_job):45247 [wandb_run.py:_redirect():2317] Redirects installed.
2025-05-18 18:50:21,701 INFO    Thread-8 (_run_job):45247 [wandb_init.py:init():1037] run started, returning control to user process
2025-05-18 18:52:01,614 WARNING MsgRouterThr:45247 [router.py:message_loop():77] message_loop has been closed
Traceback (most recent call last):
  File "/home/akshay/anaconda3/envs/ML_gpu/lib/python3.10/site-packages/wandb/sdk/interface/router_sock.py", line 28, in _read_message
    resp = self._sock_client.read_server_response(timeout=1)
  File "/home/akshay/anaconda3/envs/ML_gpu/lib/python3.10/site-packages/wandb/sdk/lib/sock_client.py", line 285, in read_server_response
    data = self._read_packet_bytes(timeout=timeout)
  File "/home/akshay/anaconda3/envs/ML_gpu/lib/python3.10/site-packages/wandb/sdk/lib/sock_client.py", line 270, in _read_packet_bytes
    raise SockClientClosedError
wandb.sdk.lib.sock_client.SockClientClosedError

The above exception was the direct cause of the following exception:

Traceback (most recent call last):
  File "/home/akshay/anaconda3/envs/ML_gpu/lib/python3.10/site-packages/wandb/sdk/interface/router.py", line 70, in message_loop
    msg = self._read_message()
  File "/home/akshay/anaconda3/envs/ML_gpu/lib/python3.10/site-packages/wandb/sdk/interface/router_sock.py", line 30, in _read_message
    raise MessageRouterClosedError from e
wandb.sdk.interface.router.MessageRouterClosedError
2025-05-18 18:52:01,616 INFO    MsgRouterThr:45247 [mailbox.py:close():115] Closing mailbox, abandoning 1 handles.
